<?xml version="1.0" ?>
<!-- =================================================================================== -->
<!-- |    This document was autogenerated by xacro from /home/ibrahim/Ros_Egitim/Projeler/Robot_Modelleme/robot_modelleme_ws/src/my_robot_description/urdf/main.xacro | -->
<!-- |    EDITING THIS FILE BY HAND IS NOT RECOMMENDED                                 | -->
<!-- =================================================================================== -->
<robot name="robot_urdf">
  <!-- xmlns:xacro = "http://www.ros.org/wiki/xacro>" kısmı xacro kullanabilmek için.-->
  <!-- xmlns:xacro = "http://www.ros.org/wiki/xacro>" kısmı xacro kullanabilmek için.-->
  <!-- Cisim merkezi tabanın ortasında değil de tabanın üstünde olsun diye link oluşturucaz .-->
  <link name="odom_link"/>
  <link name="base_link">
    <inertial>
      <mass value="5"/>
      <inertia ixx="1e-3" ixy="0.0" ixz="0.0" iyy="1e-3" iyz="0.0" izz="1e-3"/>
    </inertial>
    <visual>
      <geometry>
        <box size="0.6 0.4 0.2"/>
      </geometry>
      <origin rpy="0.0 0.0 0.0" xyz="0.0 0.0 0.0"/>
      <material name="cyan"/>
    </visual>
    <collision>
      <geometry>
        <box size="0.6 0.4 0.2"/>
      </geometry>
      <origin rpy="0.0 0.0 0.0" xyz="0.0 0.0 0.0"/>
      <material name="cyan"/>
    </collision>
  </link>
  <link name="caster_wheel_link">
    <inertial>
      <mass value="1"/>
      <inertia ixx="1e-3" ixy="0.0" ixz="0.0" iyy="1e-3" iyz="0.0" izz="1e-3"/>
    </inertial>
    <visual>
      <geometry>
        <sphere radius="0.05"/>
      </geometry>
      <origin rpy="0.0 0.0 0.0" xyz="0.0 0.0 0.0"/>
      <material name="black"/>
    </visual>
    <collision>
      <geometry>
        <sphere radius="0.05"/>
      </geometry>
      <origin rpy="0.0 0.0 0.0" xyz="0.0 0.0 0.0"/>
      <material name="black"/>
    </collision>
  </link>
  <!-- Tekerlek oluşturmada sadece tekar adı değiştiğinden tek tek tanımlamaktansa bir macro yazıyoruz-->
  <link name="right_wheel_link">
    <inertial>
      <mass value="1"/>
      <inertia ixx="1e-3" ixy="0.0" ixz="0.0" iyy="1e-3" iyz="0.0" izz="1e-3"/>
    </inertial>
    <visual>
      <geometry>
        <cylinder length="0.05" radius="0.1"/>
      </geometry>
      <origin rpy="1.5707963267948966 0.0  0.0" xyz="0.0 0.0 0.0"/>
      <!-- Tekerim yatay bir biiçimde oluşuyor ve benim istediğim gibi durması için x ekseni etrafında 90 derce döndürüyorum. 
                                                                     ( kırmızı = X , Yeşil = Y , Mavi = Z)-->
      <material name="black"/>
    </visual>
    <collision>
      <geometry>
        <cylinder length="0.05" radius="0.1"/>
      </geometry>
      <origin rpy="1.5707963267948966 0.0  0.0" xyz="0.0 0.0 0.0"/>
      <!-- Tekerim yatay bir biiçimde oluşuyor ve benim istediğim gibi durması için x ekseni etrafında 90 derce döndürüyorum. 
                                                                    ( kırmızı = X , Yeşil = Y , Mavi = Z)-->
      <material name="black"/>
    </collision>
  </link>
  <!-- Tekerlek oluşturmada sadece tekar adı değiştiğinden tek tek tanımlamaktansa bir macro yazıyoruz-->
  <link name="left_wheel_link">
    <inertial>
      <mass value="1"/>
      <inertia ixx="1e-3" ixy="0.0" ixz="0.0" iyy="1e-3" iyz="0.0" izz="1e-3"/>
    </inertial>
    <visual>
      <geometry>
        <cylinder length="0.05" radius="0.1"/>
      </geometry>
      <origin rpy="1.5707963267948966 0.0  0.0" xyz="0.0 0.0 0.0"/>
      <!-- Tekerim yatay bir biiçimde oluşuyor ve benim istediğim gibi durması için x ekseni etrafında 90 derce döndürüyorum. 
                                                                     ( kırmızı = X , Yeşil = Y , Mavi = Z)-->
      <material name="black"/>
    </visual>
    <collision>
      <geometry>
        <cylinder length="0.05" radius="0.1"/>
      </geometry>
      <origin rpy="1.5707963267948966 0.0  0.0" xyz="0.0 0.0 0.0"/>
      <!-- Tekerim yatay bir biiçimde oluşuyor ve benim istediğim gibi durması için x ekseni etrafında 90 derce döndürüyorum. 
                                                                    ( kırmızı = X , Yeşil = Y , Mavi = Z)-->
      <material name="black"/>
    </collision>
  </link>
  <joint name="base_joint" type="fixed">
    <parent link="odom_link"/>
    <child link="base_link"/>
    <origin rpy="0.0 0.0 0.0" xyz="0 0 0.2"/>
  </joint>
  <joint name="base_right_wheel_joint" type="continuous">
    <parent link="base_link"/>
    <child link="right_wheel_link"/>
    <origin rpy="0.0 0.0 0.0" xyz="-0.19999999999999998 -0.225 -0.1"/>
    <axis xyz="0 1 0.0"/>
    <!-- Cismin hangi eksenlerde dönüşüne müsaade ettiğimiz.-->
    <!--Duruş ayarlandıktan sonra bakıyoruz yeşil yani y ekseni etrafında dönmeli-->
    <limit effort="0.0" lower="0.0" upper="0.0" velocity="0.0"/>
  </joint>
  <joint name="base_left_wheel_joint" type="continuous">
    <parent link="base_link"/>
    <child link="left_wheel_link"/>
    <origin rpy="0.0 0.0 0.0" xyz="-0.19999999999999998 0.225 -0.1"/>
    <axis xyz="0 1 0.0"/>
    <!-- Cismin hangi eksenlerde dönüşüne müsaade ettiğimiz.-->
    <!--Duruş ayarlandıktan sonra bakıyoruz yeşil yani y ekseni etrafında dönmeli-->
    <limit effort="0.0" lower="0.0" upper="0.0" velocity="0.0"/>
  </joint>
  <joint name="base_caster_wheel_joint" type="fixed">
    <parent link="base_link"/>
    <child link="caster_wheel_link"/>
    <origin rpy="0.0 0.0 0.0" xyz="0.15 0 -0.15000000000000002"/>
  </joint>
  <!-- xmlns:xacro = "http://www.ros.org/wiki/xacro>" kısmı xacro kullanabilmek için.-->
  <material name="cyan">
    <color rgba="0 1 1 1"/>
  </material>
  <material name="black">
    <color rgba="0 0 0 1"/>
  </material>
</robot>
